Workbook
Name \0: '[1]#REF'!$B$76
Name \C: #REF!
Name \D: #REF!
Name \L: '[2]LAC vs Plan'!#REF!
Name \M: '[1]#REF'!$B$78
Name \P: '[2]LAC vs Plan'!#REF!
Name \R: '[2]LAC vs Plan'!#REF!
Name \V: '[1]#REF'!$I$38
Name ___MDB2: #REF!
Name ___MDB3: #REF!
Name __MDB2: #REF!
Name __MDB3: #REF!
Name __tax1: '[3]Weekly Status'!$N$34
Name __TAX2: #REF!
Name __TOT1: #REF!
Name _0066__IRELAND: OFFSET([4]Parameters!$B$7,0,0,[4]ParamData!$A$54,1)
Name _1996_ACTUALS: #REF!
Name _1997_ACTUALS: #REF!
Name _2430ME: [5]DATA!$AQ$13
Name _2430SE: [5]DATA!$AQ$12
Name _4accountPLACT_Crosstab1_Crosstab1: #REF!
Name _4accountPLACT_Crosstab1_Crosstab1_Columns: #REF!
Name _4accountPLACT_Crosstab1_Crosstab1_Measure: #REF!
Name _4accountPLACT_Crosstab1_Crosstab1_Rows: #REF!
Name _4accountPLPLAN_Crosstab1_Crosstab1: #REF!
Name _4accountPLPLAN_Crosstab1_Crosstab1_Columns: #REF!
Name _4accountPLPLAN_Crosstab1_Crosstab1_Measure: #REF!
Name _4accountPLPLAN_Crosstab1_Crosstab1_Rows: #REF!
Name _ACT2003: #REF!
Name _Lrp1: #REF!
Name _lrp2: #REF!
Name _PY2: [6]HistoryLC!$A$2:$P$128
Name _rol2: '[7]Rol 2'!$A$1:$E$444
Name _RPM1: #REF!
Name _RPM18: #REF!
Name _tax1: '[3]Weekly Status'!$N$34
Name _TAX2: #REF!
Name _TOT1: #REF!
Name _UPD2004: #REF!
Name A: #REF!
Name aaa: #REF!
Name AB: '[8]2006 BID SCHEDULE'!$A$4:$R$295
Name ABBOTTPL: #REF!
Name Abbt: #REF!
Name ABT_CC: #REF!
Name ABT_Comp_Code: #REF!
Name ABT_Ledger: [9]Codes!#REF!
Name ABT_Mgmt: #REF!
Name AbtMrgExch: #REF!
Name AbtSlsExch: #REF!
Name ABV_CC: #REF!
Name ABV_Comp_Code: #REF!
Name Account: #REF!
Name Account_Description: #REF!
Name Accr_Type: [9]Codes!#REF!
Name Acct: #REF!
Name ACCTINC: #REF!
Name AcctIncExch: #REF!
Name AcctInvestExch: #REF!
Name ACCTINVESTMENT: #REF!

Sheet OUS
F2: JE naming standardization catalogue
A4: T Code* | C4: List - Text: | D4: FB50 | F4: Total Debit : | G4: =SUMIF(OUS!$C$23:$C$10029,"DR",OUS!$D$23:$D$10029)/IF(OR(OUS!D10="EUR",OUS!D10="GBP",OUS!D10="AUD",OUS!D10="NZD"),1/VLOOKUP(OUS!$D$10,'[61]b20 MASTER (100K USD RCA check)'!$E:$AK,33,0),VLOOKUP(OUS!$D$10,'[61]b20 MASTER (100K USD RCA check)'!$E:$AK,33,0)) -> 56043.719 | H4: OUS
A5: Emergency Entry* | C5: List - Text: | D5: NO | F5: Total Credit : | G5: =SUMIF(OUS!$C$23:$C$10029,"CR",OUS!$D$23:$D$10029)/IF(OR(OUS!D10="EUR",OUS!D10="GBP",OUS!D10="AUD",OUS!D10="NZD"),1/VLOOKUP(OUS!$D$10,'[61]b20 MASTER (100K USD RCA check)'!$E:$AK,33,0),VLOOKUP(OUS!$D$10,'[61]b20 MASTER (100K USD RCA check)'!$E:$AK,33,0)) -> 56043.719 | H5: ="Ex. Rate: " & RIGHT('[61]b20 MASTER (100K USD RCA check)'!$AK$5,7) -> Ex. Rate: 1/2024
A6: Ledger Group | C6: List - Text:
A7: Journal Entry Type* | C7: List - Text: | D7: Accruals / Provisions | F7: =IFERROR(IF(OR(G4>=100000,G5>=100000),"WARNING",""),"")
A8: Company Code* | C8: List - Text: | D8: 6120 | F8: =IFERROR(IF(OR(G4>=100000,G5>=100000),"Journal Entry amount is above 100K USD",""),"")
A9: Document Date* | C9: List - Date: | D9: 01/31/2024 | F9: =IFERROR(IF(OR(G4>=100000,G5>=100000),"PLEASE SEND JE TO RCA/Supervisior/FSS Manager for approval",""),"")
A10: Doc Currency (Defaults To CoCode Curr) | C10: List - Text: | D10: ARS
A11: Posting Date* | C11: List - Date: | D11: 01/31/2024
A12: Posting Period Override | C12: List - Text:
A13: Document Type* | C13: List - Text: | D13: SA
A14: Auto Reversal Date | C14: List - Date:
A15: Document Header Text* | C15: List - Text: | D15: F- Incentives 2023 Accrual Reversal
A16: Reversal Reason | C16: List - Text:
A17: Original SAP Doc Number | C17: List - Text:
A18: Fiscal Year Of Orig Doc # | C18: List - Text:
A19: Late Entry* | C19: List - Text: | D19: No
A21: Upl | B21: G/L Account* | C21: DR/CR Indicator* | D21: Amount In Doc Currency* | E21: Assignment Key | F21: Text* | G21: Profit Center | H21: Cost Center | I21: Internal Order | J21: WBS Element | K21: Material | L21: Plant | M21: Quantity | N21: Unit Of Measure | O21: Product | P21: Sales Organization | Q21: Distribution Channel | R21: Tax Base Amount | S21: Tax Code | T21: Tax Jurisdiction | U21: Functional Area | V21: Trading Partner | W21: Partner Profit Center | X21: Batch Number
B22: List - Text | C22: List - Text | D22: Value | E22: List - Text | F22: List - Text | G22: List - Text | H22: List - Text | I22: List - Text | J22: List - Text | K22: List - Text | L22: List - Text | M22: Value | N22: List - Text | O22: List - Text | P22: List - Text | Q22: List - Text | R22: Value | S22: List - Text | T22: List - Text | U22: List - Text | V22: List - Text | W22: List - Text | X22: List - Text
B23: 60200101 | C23: DR | D23: 258480.03 | F23: Sales Force Bonus Accrual 2023 reversal | H23: =+'REPS Support'!G101 -> 619089
B24: 60200101 | C24: CR | D24: =+'REPS Support'!N102 -> 2164605 | F24: Sales Force Bonus Accrual 2023 reversal | H24: =+'REPS Support'!G102 -> 629529
B25: 60200101 | C25: DR | D25: 1128485.4 | F25: Sales Force Bonus Accrual 2023 reversal | H25: =+'REPS Support'!G103 -> 629551
B26: 60200101 | C26: DR | D26: =+'REPS Support'!N104*-1 -> 2219755.1 | F26: Sales Force Bonus Accrual 2023 reversal | H26: =+'REPS Support'!G104 -> 642904
B27: 60200101 | C27: CR | D27: =+'REPS Support'!N105 -> 2321894 | F27: Sales Force Bonus Accrual 2023 reversal | H27: =+'REPS Support'!G105 -> 642905
B28: 60200101 | C28: DR | D28: =+'REPS Support'!N106*-1 -> 1185624 | F28: Sales Force Bonus Accrual 2023 reversal | H28: =+'REPS Support'!G106 -> 642906
B29: 60200101 | C29: CR | D29: =+'REPS Support'!N108 -> 4076725 | F29: Sales Force Bonus Accrual 2023 reversal | H29: =+'REPS Support'!G108 -> 642919
B30: 60200101 | C30: CR | D30: =+'REPS Support'!N109 -> 712392.97 | F30: Sales Force Bonus Accrual 2023 reversal | H30: =+'REPS Support'!G109 -> 642920
B31: 60200101 | C31: CR | D31: =+'REPS Support'!N110 -> 7393871 | F31: Sales Force Bonus Accrual 2023 reversal | H31: =+'REPS Support'!G110 -> 642921
B32: 60200101 | C32: CR | D32: =+'REPS Support'!N111 -> 912056.67 | F32: Sales Force Bonus Accrual 2023 reversal | H32: =+'REPS Support'!G111 -> 642922
B33: 23300101 | C33: DR | D33: =+'REPS Support'!N113 -> 12789200 | F33: Sales Force Bonus Accrual 2023 reversal | G33: 11192
B34: 60400101 | C34: CR | D34: =+'REPS Support'!I83 -> 4561334.4 | F34: Sales Force Bonus Accrual 2023 reversal | H34: =+'REPS Support'!G83 -> 619089
B35: 60400101 | C35: CR | D35: =+'REPS Support'!I84 -> 2037663.6 | F35: Sales Force Bonus Accrual 2023 reversal | H35: =+'REPS Support'!G84 -> 629529
B36: 60400101 | C36: CR | D36: =+'REPS Support'!I85 -> 2717467.2 | F36: Sales Force Bonus Accrual 2023 reversal | H36: =+'REPS Support'!G85 -> 629551
B37: 60400101 | C37: CR | D37: =+'REPS Support'!I86 -> 904680 | F37: Sales Force Bonus Accrual 2023 reversal | H37: =+'REPS Support'!G86 -> 642917
B38: 60400101 | C38: CR | D38: =+'REPS Support'!I87 -> 4632650.4 | F38: Sales Force Bonus Accrual 2023 reversal | H38: =+'REPS Support'!G87 -> 642919
B39: 60400101 | C39: CR | D39: =+'REPS Support'!I88 -> 3515131.2 | F39: Sales Force Bonus Accrual 2023 reversal | H39: =+'REPS Support'!G88 -> 642920
B40: 60400101 | C40: CR | D40: =+'REPS Support'!I89 -> 4305949.2 | F40: Sales Force Bonus Accrual 2023 reversal | H40: =+'REPS Support'!G89 -> 642921
B41: 60400101 | C41: CR | D41: =+'REPS Support'!I90 -> 2618414.4 | F41: Sales Force Bonus Accrual 2023 reversal | H41: =+'REPS Support'!G90 -> 642922
B42: 60400101 | C42: CR | D42: =+'REPS Support'!I91 -> 753900 | F42: Sales Force Bonus Accrual 2023 reversal | H42: =+'REPS Support'!G91 -> 642924
B43: 60400101 | C43: CR | D43: =+'REPS Support'!I92 -> 904680 | F43: Sales Force Bonus Accrual 2023 reversal | H43: =+'REPS Support'!G92 -> 642925
...

Sheet RPA required data
AB1: (None) | AC1: (None) | AG1: Allergan | AH1: Aesthetics | AI1: Americas Accounting
B2: Approver | C2: Salgado, Romina | E2: Reviewer | V2: Approver email | W2: =VLOOKUP(C2,Y:Z,2,0) -> romina.salgado@abbvie.com | Y2: =IF('[62]Active JE users'!$A2<>"",'[62]Active JE users'!$A2,"") -> San Andres, Quanilou | Z2: =IF('[62]Active JE users'!$D2<>"",'[62]Active JE users'!$D2,"") -> quanilou.sanandres@abbvie.com | AB2: Non-FSS Team | AC2: Allergan | AG2: CFR | AH2: AP AGN | AI2: EMEA Accounting
V3: Reviewer email | W3: =VLOOKUP(F2,Y:Z,2,0) -> #N/A | Y3: =IF('[62]Active JE users'!$A3<>"",'[62]Active JE users'!$A3,"") -> Abina, Marcelo | Z3: =IF('[62]Active JE users'!$D3<>"",'[62]Active JE users'!$D3,"") -> marcelo.abina@abbvie.com | AB3: FSS Team | AC3: CFR | AG3: Consolidations | AH3: APAC SSC
B4: Team Level | C4: BPO Team | E4: Team | F4: Americas Accounting | V4: JE Requestor | W4: =VLOOKUP(C7,Y:Z,2,0) -> virginia.sandoval@abbvie.com | Y4: =IF('[62]Active JE users'!$A4<>"",'[62]Active JE users'!$A4,"") -> Abrams, Kimberly | Z4: =IF('[62]Active JE users'!$D4<>"",'[62]Active JE users'!$D4,"") -> kimberly.abrams@abbvie.com | AB4: BPO Team | AC4: Consolidations | AG4: Corp Admin | AH4: CFR AGN
Y5: =IF('[62]Active JE users'!$A5<>"",'[62]Active JE users'!$A5,"") -> Adorna, Marie Norjasmine | Z5: =IF('[62]Active JE users'!$D5<>"",'[62]Active JE users'!$D5,"") -> marienorjasmine.adorna@abbvie.com | AC5: Corp Admin | AG5: Global Commercial HQ | AH5: EMEA SSC
Y6: =IF('[62]Active JE users'!$A6<>"",'[62]Active JE users'!$A6,"") -> Agawa Jr, Nestor | Z6: =IF('[62]Active JE users'!$D6<>"",'[62]Active JE users'!$D6,"") -> nestor.agawajr@abbvie.com | AC6: Global Commercial HQ | AG6: Pharmacyclics | AH6: FSS Americas Team
B7: JE Requestor (optional) | C7: Sandoval, Virginia | Y7: =IF('[62]Active JE users'!$A7<>"",'[62]Active JE users'!$A7,"") -> Agosto, Carlos | Z7: =IF('[62]Active JE users'!$D7<>"",'[62]Active JE users'!$D7,"") -> carlos.agostozayas@abbvie.com | AC7: Pharmacyclics | AG7: R&D | AH7: FSS US Team
B8: Carbon Copy 1 (optional) | Y8: =IF('[62]Active JE users'!$A8<>"",'[62]Active JE users'!$A8,"") -> Ahmed, Anees | Z8: =IF('[62]Active JE users'!$D8<>"",'[62]Active JE users'!$D8,"") -> anees.ahmed@abbvie.com | AC8: Tax | AG8: US Commercial | AH8: LATAM SSC
B9: Carbon Copy 2 (optional) | Y9: =IF('[62]Active JE users'!$A9<>"",'[62]Active JE users'!$A9,"") -> Aldas, Alex | Z9: =IF('[62]Active JE users'!$D9<>"",'[62]Active JE users'!$D9,"") -> alex.aldas@abbvie.com | AC9: US Commercial | AG9: US Operations | AH9: Operations AGN
B10: Carbon Copy 3 (optional) | Y10: =IF('[62]Active JE users'!$A10<>"",'[62]Active JE users'!$A10,"") -> Alfaro Castano, Marco | Z10: =IF('[62]Active JE users'!$D10<>"",'[62]Active JE users'!$D10,"") -> marco.alfarocastano@abbvie.com | AC10: Aesthetics | AH10: R&D AGN
Y11: =IF('[62]Active JE users'!$A11<>"",'[62]Active JE users'!$A11,"") -> Almaida, John Arvin | Z11: =IF('[62]Active JE users'!$D11<>"",'[62]Active JE users'!$D11,"") -> johnarvin.almaida@abbvie.com | AC11: AP AGN | AH11: Tax AGN
Y12: =IF('[62]Active JE users'!$A12<>"",'[62]Active JE users'!$A12,"") -> Alvarez, Alexandra | Z12: =IF('[62]Active JE users'!$D12<>"",'[62]Active JE users'!$D12,"") -> alexandra.alvarez@abbvie.com | AC12: APAC SSC | AH12: US Commercial AGN
Y13: =IF('[62]Active JE users'!$A13<>"",'[62]Active JE users'!$A13,"") -> Amaro, Melvin Ramon | Z13: =IF('[62]Active JE users'!$D13<>"",'[62]Active JE users'!$D13,"") -> melvinramon.amaro@abbvie.com | AC13: CFR AGN | AH13: US SSC
Y14: =IF('[62]Active JE users'!$A14<>"",'[62]Active JE users'!$A14,"") -> Amelano, Irene Kristine | Z14: =IF('[62]Active JE users'!$D14<>"",'[62]Active JE users'!$D14,"") -> irenekristine.amelano@abbvie.com | AC14: EMEA SSC
Y15: =IF('[62]Active JE users'!$A15<>"",'[62]Active JE users'!$A15,"") -> Amidei, Lara | Z15: =IF('[62]Active JE users'!$D15<>"",'[62]Active JE users'!$D15,"") -> lara.amidei@abbvie.com | AC15: FSS Americas Team
Y16: =IF('[62]Active JE users'!$A16<>"",'[62]Active JE users'!$A16,"") -> Anastasi, Matteo | Z16: =IF('[62]Active JE users'!$D16<>"",'[62]Active JE users'!$D16,"") -> matteo.anastasi@abbvie.com | AC16: FSS US Team
Y17: =IF('[62]Active JE users'!$A17<>"",'[62]Active JE users'!$A17,"") -> Anoso, Mary Grace | Z17: =IF('[62]Active JE users'!$D17<>"",'[62]Active JE users'!$D17,"") -> marygrace.anoso@abbvie.com | AC17: Global Commercial AGN
Y18: =IF('[62]Active JE users'!$A18<>"",'[62]Active JE users'!$A18,"") -> Antosiewicz, Emilia | Z18: =IF('[62]Active JE users'!$D18<>"",'[62]Active JE users'!$D18,"") -> emilia.antosiewicz@abbvie.com | AC18: LATAM SSC
Y19: =IF('[62]Active JE users'!$A19<>"",'[62]Active JE users'!$A19,"") -> Aponte Rivera, Inalvis | Z19: =IF('[62]Active JE users'!$D19<>"",'[62]Active JE users'!$D19,"") -> inalvis.aponterivera@abbvie.com | AC19: Operations AGN
Y20: =IF('[62]Active JE users'!$A20<>"",'[62]Active JE users'!$A20,"") -> Aquino Gonzalez, Karin | Z20: =IF('[62]Active JE users'!$D20<>"",'[62]Active JE users'!$D20,"") -> karin.aquino@abbvie.com | AC20: Other AGN
Y21: =IF('[62]Active JE users'!$A21<>"",'[62]Active JE users'!$A21,"") -> Araki, Koichiro | Z21: =IF('[62]Active JE users'!$D21<>"",'[62]Active JE users'!$D21,"") -> koichiro.araki@abbvie.com | AC21: R&D AGN
Y22: =IF('[62]Active JE users'!$A22<>"",'[62]Active JE users'!$A22,"") -> Arce, Dannie | Z22: =IF('[62]Active JE users'!$D22<>"",'[62]Active JE users'!$D22,"") -> dannie.arce@abbvie.com | AC22: Tax AGN
Y23: =IF('[62]Active JE users'!$A23<>"",'[62]Active JE users'!$A23,"") -> Arescheri, Elizabeth J | Z23: =IF('[62]Active JE users'!$D23<>"",'[62]Active JE users'!$D23,"") -> elizabeth.arescheri@abbvie.com | AC23: US Commercial AGN
Y24: =IF('[62]Active JE users'!$A24<>"",'[62]Active JE users'!$A24,"") -> Arias Gomez, Ivannia | Z24: =IF('[62]Active JE users'!$D24<>"",'[62]Active JE users'!$D24,"") -> ivannia.arias@abbvie.com | AC24: US SSC
Y25: =IF('[62]Active JE users'!$A25<>"",'[62]Active JE users'!$A25,"") -> Arrieta Vega, Nathalie | Z25: =IF('[62]Active JE users'!$D25<>"",'[62]Active JE users'!$D25,"") -> nathalie.arrietavega@abbvie.com | AC25: Americas Accounting
... Y27: =IF('[62]Active JE users'!$A27<>"",'[62]Active JE users'!$A27,"") -> Avula, Srinath | Z27: =IF('[62]Active JE users'!$D27<>"",'[62]Active JE users'!$D27,"") -> srinath.ayula@abbvie.com | AC27: JAPAC Accounting
Y28: =IF('[62]Active JE users'!$A28<>"",'[62]Active JE users'!$A28,"") -> Azul, Maria Tercila | Z28: =IF('[62]Active JE users'!$D28<>"",'[62]Active JE users'!$D28,"") -> mariatercila.azul@abbvie.com
Y29: =IF('[62]Active JE users'!$A29<>"",'[62]Active JE users'!$A29,"") -> Bac-Zajdel, Jowita | Z29: =IF('[62]Active JE users'!$D29<>"",'[62]Active JE users'!$D29,"") -> jowita.baczajdel@abbvie.com
Y30: =IF('[62]Active JE users'!$A30<>"",'[62]Active JE users'!$A30,"") -> Badong, Sheryl | Z30: =IF('[62]Active JE users'!$D30<>"",'[62]Active JE users'!$D30,"") -> sheryl.badong@abbvie.com
Y31: =IF('[62]Active JE users'!$A31<>"",'[62]Active JE users'!$A31,"") -> Baez Cortines, Rafael | Z31: =IF('[62]Active JE users'!$D31<>"",'[62]Active JE users'!$D31,"") -> rafael.baez@abbvie.com
Y32: =IF('[62]Active JE users'!$A32<>"",'[62]Active JE users'!$A32,"") -> Bagoly, Klara | Z32: =IF('[62]Active JE users'!$D32<>"",'[62]Active JE users'!$D32,"") -> klara.bagoly@abbvie.com
Y33: =IF('[62]Active JE users'!$A33<>"",'[62]Active JE users'!$A33,"") -> Balde, Jane | Z33: =IF('[62]Active JE users'!$D33<>"",'[62]Active JE users'!$D33,"") -> jane.balde@abbvie.com
Y34: =IF('[62]Active JE users'!$A34<>"",'[62]Active JE users'!$A34,"") -> Balza, Iga | Z34: =IF('[62]Active JE users'!$D34<>"",'[62]Active JE users'!$D34,"") -> iga.balza@abbvie.com
Y35: =IF('[62]Active JE users'!$A35<>"",'[62]Active JE users'!$A35,"") -> Bao, Yuhong | Z35: =IF('[62]Active JE users'!$D35<>"",'[62]Active JE users'!$D35,"") -> yuhong.bao@abbvie.com
Y36: =IF('[62]Active JE users'!$A36<>"",'[62]Active JE users'!$A36,"") -> Barbaz, Caitlin | Z36: =IF('[62]Active JE users'!$D36<>"",'[62]Active JE users'!$D36,"") -> caitlin.barbaz@abbvie.com
Y37: =IF('[62]Active JE users'!$A37<>"",'[62]Active JE users'!$A37,"") -> Barreda, Cyrus | Z37: =IF('[62]Active JE users'!$D37<>"",'[62]Active JE users'!$D37,"") -> cyrus.barreda@abbvie.com
Y38: =IF('[62]Active JE users'!$A38<>"",'[62]Active JE users'!$A38,"") -> Bartolucci, Alison | Z38: =IF('[62]Active JE users'!$D38<>"",'[62]Active JE users'!$D38,"") -> alison.bartolucci@pwc.com
Y39: =IF('[62]Active JE users'!$A39<>"",'[62]Active JE users'!$A39,"") -> Bauzon, Josephine | Z39: =IF('[62]Active JE users'!$D39<>"",'[62]Active JE users'!$D39,"") -> josephine.bauzon@abbvie.com
... Y942: =IF('[62]Active JE users'!$A942<>"",'[62]Active JE users'!$A942,"") | Z942: =IF('[62]Active JE users'!$D942<>"",'[62]Active JE users'!$D942,"")

Sheet REPS Support
A3: Pais | B3: Legacy | C3: CC | D3: UPI | E3: Employee Name | F3: Role | G3: Rol | H3: Team | I3: Componente 1 | J3: Componente 2 | K3: Componente 3 | L3: Componente 4 | M3: Componente 5 | N3: Componente 6 | O3: Monto Final | P3: Social charges | R3: Amount per month | S3: Social Charges per month
A4: ARG | B4: L-ABBV | C4: 642919 | E4: Employee 1 | F4: Financial Analyst | G4: REP | H4: AD | I4: 107700 | J4: 323100 | K4: 646200 | L4: 0 | M4: 269250 | N4: 269250 | O4: 1615500 | P4: =O4*0.28 -> 452340 | R4: =O4/12 -> 134625 | S4: =P4/12 -> 37695
A5: ARG | B5: L-ABBV | C5: 642919 | E5: Employee 2 | F5: Accountant | G5: REP | H5: AD | I5: 107700 | J5: 323100 | K5: 646200 | L5: 0 | M5: 269250 | N5: 269250 | O5: 1615500 | P5: =O5*0.28 -> 452340 | R5: =O5/12 -> 134625 | S5: =P5/12 -> 37695
A6: ARG | B6: L-ABBV | C6: 642920 | E6: Employee 3 | F6: Treasury Analyst | G6: DM | H6: IBD | I6: 155400 | J6: 466200 | K6: 932400 | L6: 466200 | M6: 0 | N6: 388500 | O6: 2408700 | P6: =O6*0.28 -> 674436 | R6: =O6/12 -> 200725 | S6: =P6/12 -> 56203
A7: ARG | B7: L-ABBV | C7: 642919 | E7: Employee 4 | F7: Budget Analyst | G7: DM | H7: PSO | I7: 155400 | J7: 466200 | K7: 932400 | L7: 0 | M7: 0 | N7: 0 | O7: 1554000 | P7: =O7*0.28 -> 435120 | R7: =O7/12 -> 129500 | S7: =P7/12 -> 36260
A8: ARG | B8: L-ABBV | C8: 642920 | E8: Employee 5 | F8: Financial Controller | G8: REP | H8: IBD | I8: 107700 | J8: 323100 | K8: 775440 | L8: 323100 | M8: 0 | N8: 269250 | O8: 1798590 | P8: =O8*0.28 -> 503605.2 | R8: =O8/12 -> 149882.5 | S8: =P8/12 -> 41967.1
A9: ARG | B9: L-ABBV | C9: 642920 | E9: Employee 6 | F9: Investment Banker | G9: REP | H9: IBD | I9: 107700 | J9: 323100 | K9: 516960 | L9: 323100 | M9: 0 | N9: 269250 | O9: 1540110 | P9: =O9*0.28 -> 431230.8 | R9: =O9/12 -> 128342.5 | S9: =P9/12 -> 35935.9
A10: ARG | B10: L-ABBV | C10: 642920 | E10: Employee 7 | F10: Chief Financial Officer (CFO) | G10: REP | H10: IBD | I10: 107700 | J10: 323100 | K10: 646200 | L10: 323100 | M10: 0 | N10: 269250 | O10: 1669350 | P10: =O10*0.28 -> 467418 | R10: =O10/12 -> 139112.5 | S10: =P10/12 -> 38951.5
A11: ARG | B11: L-ABBV | C11: 642920 | E11: Employee 8 | F11: Tax Manager | G11: REP | H11: IBD | I11: 107700 | J11: 323100 | K11: 646200 | L11: 323100 | M11: 0 | N11: 269250 | O11: 1669350 | P11: =O11*0.28 -> 467418 | R11: =O11/12 -> 139112.5 | S11: =P11/12 -> 38951.5
A12: ARG | B12: L-ABBV | C12: 642920 | E12: Employee 9 | F12: Risk Manager | G12: REP | H12: IBD | I12: 107700 | J12: 323100 | K12: 775440 | L12: 323100 | M12: 0 | N12: 269250 | O12: 1798590 | P12: =O12*0.28 -> 503605.2 | R12: =O12/12 -> 149882.5 | S12: =P12/12 -> 41967.1
A13: ARG | B13: L-ABBV | C13: 642920 | E13: Employee 10 | F13: FP&A Manager (Financial Planning & Analysis) | G13: REP | H13: IBD | I13: 107700 | J13: 323100 | K13: 646200 | L13: 323100 | M13: 0 | N13: 269250 | O13: 1669350 | P13: =O13*0.28 -> 467418 | R13: =O13/12 -> 139112.5 | S13: =P13/12 -> 38951.5
A14: ARG | B14: L-ABBV | C14: 619089 | E14: Employee 11 | F14: Accounts Payable/Receivable Specialist | G14: DM | H14: ONCO | I14: 155400 | J14: 466200 | K14: 932400 | L14: 777000 | M14: 388500 | N14: 388500 | O14: 3108000 | P14: =O14*0.28 -> 870240 | R14: =O14/12 -> 259000 | S14: =P14/12 -> 72520
A15: ARG | B15: L-ABBV | C15: 619089 | E15: Employee 12 | F15: Audit Manager | G15: REP | H15: ONCO | I15: 107700 | J15: 323100 | K15: 775440 | L15: 538500 | M15: 269250 | N15: 269250 | O15: 2283240 | P15: =O15*0.28 -> 639307.2 | R15: =O15/12 -> 190270 | S15: =P15/12 -> 53275.6
... A74: ARG | B74: L-ABBV | C74: 642922 | E74: Employee 71 | F74: Accounts Payable/Receivable Specialist | G74: REP | H74: SPA - REUMA | I74: 107700 | J74: 323100 | K74: 646200 | L74: 0 | M74: 0 | N74: 0 | O74: 1077000 | P74: =O74*0.28 -> 301560 | R74: =O74/12 -> 89750 | S74: =P74/12 -> 25130
I75: =SUM(I4:I74) -> 8028300 | J75: =SUM(J4:J74) -> 24084900 | K75: =SUM(K4:K74) -> 47705280 | L75: =SUM(L4:L74) -> 7417500 | M75: =SUM(M4:M74) -> 4893450 | N75: =SUM(N4:N74) -> 5204250 | O75: =SUM(O4:O74) -> 97333680 | P75: =SUM(P4:P74) -> 27253430 | R75: =SUM(R4:R74) -> 8111140 | S75: =SUM(S4:S74) -> 2271119.2
R76: =R75/O75 -> 0.083333333 | S76: =S75/P75 -> 0.083333333
N77: G/L | O77: 23300101 | P77: 24820101
P79: Translation:
G80: Accrual updated with the new amounts validated by HR, FD, and GM | P80: Hello Romi, how are you doing?
G82: Row Labels | H82: Sum of Monto Final | I82: Sum of Social charges | P82: I am sharing the support to book the Annual Incentives of Argentina
G83: 619089 | H83: 16290480 | I83: 4561334.4
G84: 629529 | H84: 7277370 | I84: 2037663.6 | P84: Any doubt , let me know
G85: 629551 | H85: 9705240 | I85: 2717467.2
G86: 642917 | H86: 3231000 | I86: 904680 | P86: Many thanks
G87: 642919 | H87: 16545180 | I87: 4632650.4
G88: 642920 | H88: 12554040 | I88: 3515131.2 | P88: Regards,
G89: 642921 | H89: 15378390 | I89: 4305949.2
G90: 642922 | H90: 9351480 | I90: 2618414.4 | P90: Fede
G91: 642924 | H91: 2692500 | I91: 753900
G92: 642925 | H92: 3231000 | I92: 904680
G93: 642927 | H93: 1077000 | I93: 301560
G94: Grand Total | H94: 97333680 | I94: 27253430
G95: G/L | H95: 23300101 | I95: 24820101
I96: to reverse
G98: Paid
G99: ABBVIE | H99: GL Report | J99: PERÍODO mm-2022
G100: CC | H100: Wage Type TMF | I100: Wage Type | J100: Wage Type Abbott | K100: GL Account | L100: Debe | M100: Haber | N100: To reverse
G101: 619089 | H101: 1120 | I101: 16570 | J101: Special Award | K101: 23300101 | L101: 16548960 | M101: =VLOOKUP(G101,$G$116:$H$126,2,FALSE) -> 16290480 | N101: =+M101-L101 -> -258480.02
G102: 629529 | H102: 1120 | I102: 16570 | J102: Special Award | K102: 23300101 | L102: 5112765 | M102: =VLOOKUP(G102,$G$116:$H$126,2,FALSE) -> 7277370 | N102: =+M102-L102 -> 2164605
G103: 629551 | H103: 1120 | I103: 16570 | J103: Special Award | K103: 23300101 | L103: 10833725 | M103: =VLOOKUP(G103,$G$116:$H$126,2,FALSE) -> 9705240 | N103: =+M103-L103 -> -1128485.4
...

Sheet 24820101
A2: Type | B2: Accrued Employer Social Taxes 24820101 | D2: Comments
A3: L | B3: Payables - Social Charges Payroll September '22 | C3: =-'[63]Payroll P9'!L3 -> -44157451 | D3: Correct | H3: Non OIM Details
A4: L | B4: Accrual - Social Change Vacation Nov'21 to Oct'22 | C4: =-GETPIVOTDATA("Sum of Cargas SOC",'[63]2021 SC Vacation'!$O$3) -> #REF! | D4: Correct
A5: L | B5: Accual - Sales - Force Bonus YTD 22 | C5: =-'[63]2022 Sales force Bonus'!V19 -> -9110820.5 | D5: Correct
A6: L | B6: 13th Salary Accrual P9 2022 | C6: =-'[63]13th Salary'!AC53 -> -7471547.6 | D6: Correct
A7: R | B7: Difference SC Payroll between P6'22 and Payment done in P7'22 | C7: ='[63]Dif payroll and payment '!J10 -> 140901.41 | D7: investigate with payroll
A8: R | B8: Difference SC Payroll between P7'22 and Payment done in P8'22 | C8: ='[63]Dif payroll and payment '!J21 -> 11006.88 | D8: investigate with payroll
A9: R | B9: Difference SC Payroll between P8'22 and Payment done in P9'22 | C9: ='[63]Dif payroll and payment '!J28 -> -77772.13 | D9: investigate with payroll
B11: L-Items | C11: =SUM(C3:C6) -> #REF!
B12: R-Items | C12: =SUM(C7:C10) -> 74136.16 | E12: TMF analisys to support the adj
B13: Total | C13: =SUM(C11:C12) -> #REF!
B14: SAP | C14: -79711041
B15: Difference | C15: =+C13-C14 -> #REF!
B17: Data download from SAP PEP (Production), using transaction FS10N (Balance Display: G/L Accounts For the Ledger 0L)

Sheet JE Type Validations
A1: Accruals / Provisions
A2: Allocation
A3: Banking Related
A4: Correction due to System Issue
A5: Intercompany
A6: Inventory Related
A7: Other
A8: Other Corrections (Reversal)
A9: Other Receivables and Pre-payment
A10: Payroll Related
A11: Reclass
A12: R-Item Write-off
... A15: Taxonomy reclass due to newly approved Product Category - GL account combination
